reported_result/report-3/ART_ISP/output/output7.txt

Limit	1	2	6	8	3	BUY 	0	FAK	0
NewOrderRs	Rejected
	Trades	0
	Orders	0
	Credits	7
	Credit	1	5
	Credit	2	3
	Credit	3	5
	Credit	4	14
	Credit	5	14
	Credit	6	18
	Credit	7	11
	Ownerships	7
	Ownership	1	12
	Ownership	2	66
	Ownership	3	70
	Ownership	4	63
	Ownership	5	52
	Ownership	6	49
	Ownership	7	57
	ReferencePrice	5
	StaticPriceBandLowerLimit	0.6
	StaticPriceBandUpperLimit	0.8
	TotalShares	100
	OwnershipUpperLimit	0.2
	TickSize	1
	LotSize	1
Iceberg	2	3	3	9	1	BUY 	1	---	0
NewOrderRs	Rejected
	Trades	0
	Orders	0
	Credits	7
	Credit	1	5
	Credit	2	3
	Credit	3	5
	Credit	4	14
	Credit	5	14
	Credit	6	18
	Credit	7	11
	Ownerships	7
	Ownership	1	12
	Ownership	2	66
	Ownership	3	70
	Ownership	4	63
	Ownership	5	52
	Ownership	6	49
	Ownership	7	57
	ReferencePrice	5
	StaticPriceBandLowerLimit	0.6
	StaticPriceBandUpperLimit	0.8
	TotalShares	100
	OwnershipUpperLimit	0.2
	TickSize	1
	LotSize	1
Limit	3	5	3	2	2	BUY 	0	---	0
NewOrderRs	Rejected
	Trades	0
	Orders	0
	Credits	7
	Credit	1	5
	Credit	2	3
	Credit	3	5
	Credit	4	14
	Credit	5	14
	Credit	6	18
	Credit	7	11
	Ownerships	7
	Ownership	1	12
	Ownership	2	66
	Ownership	3	70
	Ownership	4	63
	Ownership	5	52
	Ownership	6	49
	Ownership	7	57
	ReferencePrice	5
	StaticPriceBandLowerLimit	0.6
	StaticPriceBandUpperLimit	0.8
	TotalShares	100
	OwnershipUpperLimit	0.2
	TickSize	1
	LotSize	1
Limit	4	1	1	4	5	BUY 	1	---	0
NewOrderRs	Eliminated
	Trades	0
	Orders	0
	Credits	7
	Credit	1	5
	Credit	2	3
	Credit	3	5
	Credit	4	14
	Credit	5	14
	Credit	6	18
	Credit	7	11
	Ownerships	7
	Ownership	1	12
	Ownership	2	66
	Ownership	3	70
	Ownership	4	63
	Ownership	5	52
	Ownership	6	49
	Ownership	7	57
	ReferencePrice	5
	StaticPriceBandLowerLimit	0.6
	StaticPriceBandUpperLimit	0.8
	TotalShares	100
	OwnershipUpperLimit	0.2
	TickSize	1
	LotSize	1
CancelOrderRs	Rejected
	Orders	0
	Credits	7
	Credit	1	5
	Credit	2	3
	Credit	3	5
	Credit	4	14
	Credit	5	14
	Credit	6	18
	Credit	7	11
	Ownerships	7
	Ownership	1	12
	Ownership	2	66
	Ownership	3	70
	Ownership	4	63
	Ownership	5	52
	Ownership	6	49
	Ownership	7	57
	ReferencePrice	5
	StaticPriceBandLowerLimit	0.6
	StaticPriceBandUpperLimit	0.8
	TotalShares	100
	OwnershipUpperLimit	0.2
	TickSize	1
	LotSize	1
Limit	6	5	1	8	4	SELL	0	---	0
NewOrderRs	Accepted
	Trades	0
	Orders	1
	Order	Limit	6	5	1	8	4	SELL	0	---	0
	Credits	7
	Credit	1	5
	Credit	2	3
	Credit	3	5
	Credit	4	14
	Credit	5	14
	Credit	6	18
	Credit	7	11
	Ownerships	7
	Ownership	1	12
	Ownership	2	66
	Ownership	3	70
	Ownership	4	63
	Ownership	5	52
	Ownership	6	49
	Ownership	7	57
	ReferencePrice	5
	StaticPriceBandLowerLimit	0.6
	StaticPriceBandUpperLimit	0.8
	TotalShares	100
	OwnershipUpperLimit	0.2
	TickSize	1
	LotSize	1
Limit	7	2	2	8	6	BUY 	5	---	0
NewOrderRs	Rejected
	Trades	0
	Orders	1
	Order	Limit	6	5	1	8	4	SELL	0	---	0
	Credits	7
	Credit	1	5
	Credit	2	3
	Credit	3	5
	Credit	4	14
	Credit	5	14
	Credit	6	18
	Credit	7	11
	Ownerships	7
	Ownership	1	12
	Ownership	2	66
	Ownership	3	70
	Ownership	4	63
	Ownership	5	52
	Ownership	6	49
	Ownership	7	57
	ReferencePrice	5
	StaticPriceBandLowerLimit	0.6
	StaticPriceBandUpperLimit	0.8
	TotalShares	100
	OwnershipUpperLimit	0.2
	TickSize	1
	LotSize	1
Limit	8	5	4	8	5	SELL	0	---	0
NewOrderRs	Accepted
	Trades	0
	Orders	2
	Order	Limit	6	5	1	8	4	SELL	0	---	0
	Order	Limit	8	5	4	8	5	SELL	0	---	0
	Credits	7
	Credit	1	5
	Credit	2	3
	Credit	3	5
	Credit	4	14
	Credit	5	14
	Credit	6	18
	Credit	7	11
	Ownerships	7
	Ownership	1	12
	Ownership	2	66
	Ownership	3	70
	Ownership	4	63
	Ownership	5	52
	Ownership	6	49
	Ownership	7	57
	ReferencePrice	5
	StaticPriceBandLowerLimit	0.6
	StaticPriceBandUpperLimit	0.8
	TotalShares	100
	OwnershipUpperLimit	0.2
	TickSize	1
	LotSize	1
Limit	9	1	1	8	4	SELL	0	---	0
NewOrderRs	Accepted
	Trades	0
	Orders	3
	Order	Limit	6	5	1	8	4	SELL	0	---	0
	Order	Limit	8	5	4	8	5	SELL	0	---	0
	Order	Limit	9	1	1	8	4	SELL	0	---	0
	Credits	7
	Credit	1	5
	Credit	2	3
	Credit	3	5
	Credit	4	14
	Credit	5	14
	Credit	6	18
	Credit	7	11
	Ownerships	7
	Ownership	1	12
	Ownership	2	66
	Ownership	3	70
	Ownership	4	63
	Ownership	5	52
	Ownership	6	49
	Ownership	7	57
	ReferencePrice	5
	StaticPriceBandLowerLimit	0.6
	StaticPriceBandUpperLimit	0.8
	TotalShares	100
	OwnershipUpperLimit	0.2
	TickSize	1
	LotSize	1
Limit	10	1	1	5	5	SELL	0	---	0
ReplaceOrderRs	Accepted
	Trades	0
	Orders	3
	Order	Limit	10	1	1	5	5	SELL	0	---	0
	Order	Limit	6	5	1	8	4	SELL	0	---	0
	Order	Limit	8	5	4	8	5	SELL	0	---	0
	Credits	7
	Credit	1	5
	Credit	2	3
	Credit	3	5
	Credit	4	14
	Credit	5	14
	Credit	6	18
	Credit	7	11
	Ownerships	7
	Ownership	1	12
	Ownership	2	66
	Ownership	3	70
	Ownership	4	63
	Ownership	5	52
	Ownership	6	49
	Ownership	7	57
	ReferencePrice	5
	StaticPriceBandLowerLimit	0.6
	StaticPriceBandUpperLimit	0.8
	TotalShares	100
	OwnershipUpperLimit	0.2
	TickSize	1
	LotSize	1
Limit	11	5	1	8	1	BUY 	1	---	0
NewOrderRs	Accepted
	Trades	1
	Trade	5	1	11	10
	Orders	3
	Order	Limit	10	1	1	5	4	SELL	0	---	0
	Order	Limit	6	5	1	8	4	SELL	0	---	0
	Order	Limit	8	5	4	8	5	SELL	0	---	0
	Credits	7
	Credit	1	10
	Credit	2	3
	Credit	3	5
	Credit	4	14
	Credit	5	9
	Credit	6	18
	Credit	7	11
	Ownerships	7
	Ownership	1	12
	Ownership	2	66
	Ownership	3	70
	Ownership	4	63
	Ownership	5	52
	Ownership	6	49
	Ownership	7	57
	ReferencePrice	5
	StaticPriceBandLowerLimit	0.6
	StaticPriceBandUpperLimit	0.8
	TotalShares	100
	OwnershipUpperLimit	0.2
	TickSize	1
	LotSize	1
Iceberg	12	5	4	3	3	BUY 	3	---	0
NewOrderRs	Rejected
	Trades	0
	Orders	3
	Order	Limit	10	1	1	5	4	SELL	0	---	0
	Order	Limit	6	5	1	8	4	SELL	0	---	0
	Order	Limit	8	5	4	8	5	SELL	0	---	0
	Credits	7
	Credit	1	10
	Credit	2	3
	Credit	3	5
	Credit	4	14
	Credit	5	9
	Credit	6	18
	Credit	7	11
	Ownerships	7
	Ownership	1	12
	Ownership	2	66
	Ownership	3	70
	Ownership	4	63
	Ownership	5	52
	Ownership	6	49
	Ownership	7	57
	ReferencePrice	5
	StaticPriceBandLowerLimit	0.6
	StaticPriceBandUpperLimit	0.8
	TotalShares	100
	OwnershipUpperLimit	0.2
	TickSize	1
	LotSize	1
Iceberg	13	6	4	9	6	SELL	0	---	0
NewOrderRs	Accepted
	Trades	0
	Orders	4
	Order	Limit	10	1	1	5	4	SELL	0	---	0
	Order	Limit	6	5	1	8	4	SELL	0	---	0
	Order	Limit	8	5	4	8	5	SELL	0	---	0
	Order	Iceberg	13	6	4	9	6	SELL	0	---	6
	Credits	7
	Credit	1	10
	Credit	2	3
	Credit	3	5
	Credit	4	14
	Credit	5	9
	Credit	6	18
	Credit	7	11
	Ownerships	7
	Ownership	1	12
	Ownership	2	66
	Ownership	3	70
	Ownership	4	63
	Ownership	5	52
	Ownership	6	49
	Ownership	7	57
	ReferencePrice	5
	StaticPriceBandLowerLimit	0.6
	StaticPriceBandUpperLimit	0.8
	TotalShares	100
	OwnershipUpperLimit	0.2
	TickSize	1
	LotSize	1
Limit	14	3	4	5	8	BUY 	0	---	0
NewOrderRs	Rejected
	Trades	0
	Orders	4
	Order	Limit	10	1	1	5	4	SELL	0	---	0
	Order	Limit	6	5	1	8	4	SELL	0	---	0
	Order	Limit	8	5	4	8	5	SELL	0	---	0
	Order	Iceberg	13	6	4	9	6	SELL	0	---	6
	Credits	7
	Credit	1	10
	Credit	2	3
	Credit	3	5
	Credit	4	14
	Credit	5	9
	Credit	6	18
	Credit	7	11
	Ownerships	7
	Ownership	1	12
	Ownership	2	66
	Ownership	3	70
	Ownership	4	63
	Ownership	5	52
	Ownership	6	49
	Ownership	7	57
	ReferencePrice	5
	StaticPriceBandLowerLimit	0.6
	StaticPriceBandUpperLimit	0.8
	TotalShares	100
	OwnershipUpperLimit	0.2
	TickSize	1
	LotSize	1
CancelOrderRs	Rejected
	Orders	4
	Order	Limit	10	1	1	5	4	SELL	0	---	0
	Order	Limit	6	5	1	8	4	SELL	0	---	0
	Order	Limit	8	5	4	8	5	SELL	0	---	0
	Order	Iceberg	13	6	4	9	6	SELL	0	---	6
	Credits	7
	Credit	1	10
	Credit	2	3
	Credit	3	5
	Credit	4	14
	Credit	5	9
	Credit	6	18
	Credit	7	11
	Ownerships	7
	Ownership	1	12
	Ownership	2	66
	Ownership	3	70
	Ownership	4	63
	Ownership	5	52
	Ownership	6	49
	Ownership	7	57
	ReferencePrice	5
	StaticPriceBandLowerLimit	0.6
	StaticPriceBandUpperLimit	0.8
	TotalShares	100
	OwnershipUpperLimit	0.2
	TickSize	1
	LotSize	1
Iceberg	16	4	6	4	5	BUY 	0	---	0
NewOrderRs	Rejected
	Trades	0
	Orders	4
	Order	Limit	10	1	1	5	4	SELL	0	---	0
	Order	Limit	6	5	1	8	4	SELL	0	---	0
	Order	Limit	8	5	4	8	5	SELL	0	---	0
	Order	Iceberg	13	6	4	9	6	SELL	0	---	6
	Credits	7
	Credit	1	10
	Credit	2	3
	Credit	3	5
	Credit	4	14
	Credit	5	9
	Credit	6	18
	Credit	7	11
	Ownerships	7
	Ownership	1	12
	Ownership	2	66
	Ownership	3	70
	Ownership	4	63
	Ownership	5	52
	Ownership	6	49
	Ownership	7	57
