reported_result/report-3/ART_TFC/output/output1.txt

Limit	1	5	1	3	6	SELL	0	---	0
NewOrderRs	Accepted
	Trades	0
	Orders	1
	Order	Limit	1	5	1	3	6	SELL	0	---	0
	Credits	7
	Credit	1	13
	Credit	2	1
	Credit	3	16
	Credit	4	3
	Credit	5	15
	Credit	6	10
	Credit	7	15
	Ownerships	7
	Ownership	1	41
	Ownership	2	32
	Ownership	3	10
	Ownership	4	75
	Ownership	5	87
	Ownership	6	71
	Ownership	7	67
	ReferencePrice	5
	StaticPriceBandLowerLimit	0.6
	StaticPriceBandUpperLimit	0.8
	TotalShares	100
	OwnershipUpperLimit	0.2
	TickSize	1
	LotSize	1
Iceberg	2	7	4	7	8	SELL	1	---	0
NewOrderRs	Eliminated
	Trades	0
	Orders	1
	Order	Limit	1	5	1	3	6	SELL	0	---	0
	Credits	7
	Credit	1	13
	Credit	2	1
	Credit	3	16
	Credit	4	3
	Credit	5	15
	Credit	6	10
	Credit	7	15
	Ownerships	7
	Ownership	1	41
	Ownership	2	32
	Ownership	3	10
	Ownership	4	75
	Ownership	5	87
	Ownership	6	71
	Ownership	7	67
	ReferencePrice	5
	StaticPriceBandLowerLimit	0.6
	StaticPriceBandUpperLimit	0.8
	TotalShares	100
	OwnershipUpperLimit	0.2
	TickSize	1
	LotSize	1
Limit	3	1	5	2	5	SELL	0	FAK	0
NewOrderRs	Eliminated
	Trades	0
	Orders	1
	Order	Limit	1	5	1	3	6	SELL	0	---	0
	Credits	7
	Credit	1	13
	Credit	2	1
	Credit	3	16
	Credit	4	3
	Credit	5	15
	Credit	6	10
	Credit	7	15
	Ownerships	7
	Ownership	1	41
	Ownership	2	32
	Ownership	3	10
	Ownership	4	75
	Ownership	5	87
	Ownership	6	71
	Ownership	7	67
	ReferencePrice	5
	StaticPriceBandLowerLimit	0.6
	StaticPriceBandUpperLimit	0.8
	TotalShares	100
	OwnershipUpperLimit	0.2
	TickSize	1
	LotSize	1
Limit	4	2	6	3	6	SELL	0	---	0
NewOrderRs	Accepted
	Trades	0
	Orders	2
	Order	Limit	1	5	1	3	6	SELL	0	---	0
	Order	Limit	4	2	6	3	6	SELL	0	---	0
	Credits	7
	Credit	1	13
	Credit	2	1
	Credit	3	16
	Credit	4	3
	Credit	5	15
	Credit	6	10
	Credit	7	15
	Ownerships	7
	Ownership	1	41
	Ownership	2	32
	Ownership	3	10
	Ownership	4	75
	Ownership	5	87
	Ownership	6	71
	Ownership	7	67
	ReferencePrice	5
	StaticPriceBandLowerLimit	0.6
	StaticPriceBandUpperLimit	0.8
	TotalShares	100
	OwnershipUpperLimit	0.2
	TickSize	1
	LotSize	1
CancelOrderRs	Accepted
	Orders	1
	Order	Limit	1	5	1	3	6	SELL	0	---	0
	Credits	7
	Credit	1	13
	Credit	2	1
	Credit	3	16
	Credit	4	3
	Credit	5	15
	Credit	6	10
	Credit	7	15
	Ownerships	7
	Ownership	1	41
	Ownership	2	32
	Ownership	3	10
	Ownership	4	75
	Ownership	5	87
	Ownership	6	71
	Ownership	7	67
	ReferencePrice	5
	StaticPriceBandLowerLimit	0.6
	StaticPriceBandUpperLimit	0.8
	TotalShares	100
	OwnershipUpperLimit	0.2
	TickSize	1
	LotSize	1
Limit	6	6	1	9	5	SELL	0	---	0
NewOrderRs	Accepted
	Trades	0
	Orders	2
	Order	Limit	1	5	1	3	6	SELL	0	---	0
	Order	Limit	6	6	1	9	5	SELL	0	---	0
	Credits	7
	Credit	1	13
	Credit	2	1
	Credit	3	16
	Credit	4	3
	Credit	5	15
	Credit	6	10
	Credit	7	15
	Ownerships	7
	Ownership	1	41
	Ownership	2	32
	Ownership	3	10
	Ownership	4	75
	Ownership	5	87
	Ownership	6	71
	Ownership	7	67
	ReferencePrice	5
	StaticPriceBandLowerLimit	0.6
	StaticPriceBandUpperLimit	0.8
	TotalShares	100
	OwnershipUpperLimit	0.2
	TickSize	1
	LotSize	1
Limit	7	6	3	9	4	BUY 	0	---	0
NewOrderRs	Rejected
	Trades	0
	Orders	2
	Order	Limit	1	5	1	3	6	SELL	0	---	0
	Order	Limit	6	6	1	9	5	SELL	0	---	0
	Credits	7
	Credit	1	13
	Credit	2	1
	Credit	3	16
	Credit	4	3
	Credit	5	15
	Credit	6	10
	Credit	7	15
	Ownerships	7
	Ownership	1	41
	Ownership	2	32
	Ownership	3	14
	Ownership	4	75
	Ownership	5	87
	Ownership	6	71
	Ownership	7	67
	ReferencePrice	5
	StaticPriceBandLowerLimit	0.6
	StaticPriceBandUpperLimit	0.8
	TotalShares	100
	OwnershipUpperLimit	0.2
	TickSize	1
	LotSize	1
Iceberg	8	1	7	5	2	SELL	0	---	0
NewOrderRs	Accepted
	Trades	0
	Orders	3
	Order	Limit	1	5	1	3	6	SELL	0	---	0
	Order	Iceberg	8	1	7	5	2	SELL	0	---	1
	Order	Limit	6	6	1	9	5	SELL	0	---	0
	Credits	7
	Credit	1	13
	Credit	2	1
	Credit	3	16
	Credit	4	3
	Credit	5	15
	Credit	6	10
	Credit	7	15
	Ownerships	7
	Ownership	1	41
	Ownership	2	32
	Ownership	3	14
	Ownership	4	75
	Ownership	5	87
	Ownership	6	71
	Ownership	7	67
	ReferencePrice	5
	StaticPriceBandLowerLimit	0.6
	StaticPriceBandUpperLimit	0.8
	TotalShares	100
	OwnershipUpperLimit	0.2
	TickSize	1
	LotSize	1
Iceberg	9	5	2	5	4	SELL	1	---	0
NewOrderRs	Eliminated
	Trades	0
	Orders	3
	Order	Limit	1	5	1	3	6	SELL	0	---	0
	Order	Iceberg	8	1	7	5	2	SELL	0	---	1
	Order	Limit	6	6	1	9	5	SELL	0	---	0
	Credits	7
	Credit	1	13
	Credit	2	1
	Credit	3	16
	Credit	4	3
	Credit	5	15
	Credit	6	10
	Credit	7	15
	Ownerships	7
	Ownership	1	41
	Ownership	2	32
	Ownership	3	14
	Ownership	4	75
	Ownership	5	87
	Ownership	6	71
	Ownership	7	67
	ReferencePrice	5
	StaticPriceBandLowerLimit	0.6
	StaticPriceBandUpperLimit	0.8
	TotalShares	100
	OwnershipUpperLimit	0.2
	TickSize	1
	LotSize	1
Limit	10	5	2	6	5	SELL	0	FAK	0
ReplaceOrderRs	Rejected
	Trades	0
	Orders	3
	Order	Limit	1	5	1	3	6	SELL	0	---	0
	Order	Iceberg	8	1	7	5	2	SELL	0	---	1
	Order	Limit	6	6	1	9	5	SELL	0	---	0
	Credits	7
	Credit	1	13
	Credit	2	1
	Credit	3	16
	Credit	4	3
	Credit	5	15
	Credit	6	10
	Credit	7	15
	Ownerships	7
	Ownership	1	41
	Ownership	2	32
	Ownership	3	14
	Ownership	4	75
	Ownership	5	87
	Ownership	6	71
	Ownership	7	67
	ReferencePrice	5
	StaticPriceBandLowerLimit	0.6
	StaticPriceBandUpperLimit	0.8
	TotalShares	100
	OwnershipUpperLimit	0.2
	TickSize	1
	LotSize	1
Limit	11	6	4	8	8	BUY 	4	---	0
NewOrderRs	Rejected
	Trades	0
	Orders	3
	Order	Limit	1	5	1	3	6	SELL	0	---	0
	Order	Iceberg	8	1	7	5	2	SELL	0	---	1
	Order	Limit	6	6	1	9	5	SELL	0	---	0
	Credits	7
	Credit	1	13
	Credit	2	1
	Credit	3	16
	Credit	4	3
	Credit	5	15
	Credit	6	10
	Credit	7	15
	Ownerships	7
	Ownership	1	41
	Ownership	2	32
	Ownership	3	14
	Ownership	4	75
	Ownership	5	87
	Ownership	6	71
	Ownership	7	67
	ReferencePrice	5
	StaticPriceBandLowerLimit	0.6
	StaticPriceBandUpperLimit	0.8
	TotalShares	100
	OwnershipUpperLimit	0.2
	TickSize	1
	LotSize	1
Limit	12	6	2	7	1	BUY 	0	---	0
NewOrderRs	Rejected
	Trades	0
	Orders	3
	Order	Limit	1	5	1	3	6	SELL	0	---	0
	Order	Iceberg	8	1	7	5	2	SELL	0	---	1
	Order	Limit	6	6	1	9	5	SELL	0	---	0
	Credits	7
	Credit	1	13
	Credit	2	1
	Credit	3	16
	Credit	4	3
	Credit	5	15
	Credit	6	10
	Credit	7	15
	Ownerships	7
	Ownership	1	41
	Ownership	2	32
	Ownership	3	14
	Ownership	4	75
	Ownership	5	87
	Ownership	6	71
	Ownership	7	67
	ReferencePrice	5
	StaticPriceBandLowerLimit	0.6
	StaticPriceBandUpperLimit	0.8
	TotalShares	100
	OwnershipUpperLimit	0.2
	TickSize	1
	LotSize	1
Limit	13	1	1	2	3	SELL	0	---	0
NewOrderRs	Accepted
	Trades	0
	Orders	4
	Order	Limit	13	1	1	2	3	SELL	0	---	0
	Order	Limit	1	5	1	3	6	SELL	0	---	0
	Order	Iceberg	8	1	7	5	2	SELL	0	---	1
	Order	Limit	6	6	1	9	5	SELL	0	---	0
	Credits	7
	Credit	1	13
	Credit	2	1
	Credit	3	16
	Credit	4	3
	Credit	5	15
	Credit	6	10
	Credit	7	15
	Ownerships	7
	Ownership	1	41
	Ownership	2	32
	Ownership	3	14
	Ownership	4	75
	Ownership	5	87
	Ownership	6	71
	Ownership	7	67
	ReferencePrice	5
	StaticPriceBandLowerLimit	0.6
	StaticPriceBandUpperLimit	0.8
	TotalShares	100
	OwnershipUpperLimit	0.2
	TickSize	1
	LotSize	1
Limit	14	6	1	7	7	SELL	0	FAK	0
NewOrderRs	Eliminated
	Trades	0
	Orders	4
	Order	Limit	13	1	1	2	3	SELL	0	---	0
	Order	Limit	1	5	1	3	6	SELL	0	---	0
	Order	Iceberg	8	1	7	5	2	SELL	0	---	1
	Order	Limit	6	6	1	9	5	SELL	0	---	0
	Credits	7
	Credit	1	13
	Credit	2	1
	Credit	3	16
	Credit	4	3
	Credit	5	15
	Credit	6	10
	Credit	7	15
	Ownerships	7
	Ownership	1	41
	Ownership	2	32
	Ownership	3	14
	Ownership	4	75
	Ownership	5	87
	Ownership	6	71
	Ownership	7	67
	ReferencePrice	5
	StaticPriceBandLowerLimit	0.6
	StaticPriceBandUpperLimit	0.8
	TotalShares	100
	OwnershipUpperLimit	0.2
	TickSize	1
	LotSize	1
CancelOrderRs	Rejected
	Orders	4
	Order	Limit	13	1	1	2	3	SELL	0	---	0
	Order	Limit	1	5	1	3	6	SELL	0	---	0
	Order	Iceberg	8	1	7	5	2	SELL	0	---	1
	Order	Limit	6	6	1	9	5	SELL	0	---	0
	Credits	7
	Credit	1	13
	Credit	2	1
	Credit	3	16
	Credit	4	3
	Credit	5	15
	Credit	6	10
	Credit	7	15
	Ownerships	7
	Ownership	1	41
	Ownership	2	32
	Ownership	3	14
	Ownership	4	75
	Ownership	5	87
	Ownership	6	71
	Ownership	7	67
	ReferencePrice	5
	StaticPriceBandLowerLimit	0.6
	StaticPriceBandUpperLimit	0.8
	TotalShares	100
	OwnershipUpperLimit	0.2
	TickSize	1
	LotSize	1
Iceberg	16	2	3	9	8	BUY 	0	---	0
NewOrderRs	Rejected
	Trades	0
	Orders	4
	Order	Limit	13	1	1	2	3	SELL	0	---	0
